<mujoco model="go1_description">
    <compiler angle="radian" meshdir="/home/bridge/Desktop/quadrupedal_robot_recover/legged_gym/resources/robots/go1/meshes/" autolimits="true"/>
    <size njmax="500" nconmax="100" />

    


    <asset>
        <mesh name="trunk" file="trunk.stl" />
        <mesh name="hip" file="hip.stl" />
        <mesh name="thigh_mirror" file="thigh_mirror.stl" />
        <mesh name="calf" file="calf.stl" />
        <mesh name="thigh" file="thigh.stl" />
    </asset>
    <worldbody>
        <geom size="0.0005 0.0005 0.0005" type="box" contype="0" conaffinity="0" group="1" />
        <geom type="mesh" contype="0" conaffinity="0" group="1" rgba="0.913725 0.913725 0.847059 1" mesh="trunk" />
        <geom size="0.1881 0.04675 0.057" type="box" rgba="0.913725 0.913725 0.847059 1" />
        <geom size="0.0005 0.0005 0.0005" pos="-0.01592 -0.06659 -0.00617" type="box" contype="0" conaffinity="0" group="1" rgba="0.8 0 0 1" />
        <body name="FR_hip" pos="0.1881 -0.04675 0">
            <inertial pos="-0.00541 0.00074 6e-06" quat="0.506126 0.507401 0.493705 0.492582" mass="0.510299" diaginertia="0.000591107 0.000396595 0.000305077" />
            <joint name="FR_hip_joint" pos="0 0 0" axis="1 0 0" limited="true" range="-0.802851 0.802851" />
            <geom quat="0 1 0 0" type="mesh" contype="0" conaffinity="0" group="1" rgba="0.913725 0.913725 0.847059 1" mesh="hip" />
            <geom size="0.046 0.02" pos="0 -0.045 0" quat="0.707107 0.707107 0 0" type="cylinder" rgba="0.913725 0.913725 0.847059 1" />
            <body name="FR_thigh" pos="0 -0.08 0">
                <inertial pos="-0.003468 0.018947 -0.032736" quat="0.999266 0.00067676 -0.0382978 0.000639813" mass="0.898919" diaginertia="0.00542178 0.00514246 0.000998869" />
                <joint name="FR_thigh_joint" pos="0 0 0" axis="0 1 0" limited="true" range="-1.0472 4.18879" />
                <geom type="mesh" contype="0" conaffinity="0" group="1" rgba="0.913725 0.913725 0.847059 1" mesh="thigh_mirror" />
                <geom size="0.1065 0.01225 0.017" pos="0 0 -0.1065" quat="0.707107 0 0.707107 0" type="box" rgba="0.913725 0.913725 0.847059 1" />
                <body name="FR_calf" pos="0 0 -0.213">
                    <inertial pos="0.00455603 0.0009473 -0.147239" quat="0.762045 0.00970173 0.0180098 0.647201" mass="0.218015" diaginertia="0.00399678 0.00398122 3.99428e-05" />
                    <joint name="FR_calf_joint" pos="0 0 0" axis="0 1 0" limited="true" range="-2.69653 -0.916298" />
                    <geom type="mesh" contype="0" conaffinity="0" group="1" rgba="0 0 0 1" mesh="calf" />
                    <geom size="0.1065 0.008 0.008" pos="0 0 -0.1065" quat="0.707107 0 0.707107 0" type="box" rgba="0 0 0 1" />
                    <geom size="0.01" pos="0 0 -0.213" contype="0" conaffinity="0" group="1" rgba="0 0 0 1" />
                    <geom size="0.02" pos="0 0 -0.213" rgba="0 0 0 1" />
                </body>
            </body>
        </body>
        <body name="FL_hip" pos="0.1881 0.04675 0">
            <inertial pos="-0.00541 -0.00074 6e-06" quat="0.492582 0.493705 0.507401 0.506126" mass="0.510299" diaginertia="0.000591107 0.000396595 0.000305077" />
            <joint name="FL_hip_joint" pos="0 0 0" axis="1 0 0" limited="true" range="-0.802851 0.802851" />
            <geom type="mesh" contype="0" conaffinity="0" group="1" rgba="0.913725 0.913725 0.847059 1" mesh="hip" />
            <geom size="0.046 0.02" pos="0 0.045 0" quat="0.707107 0.707107 0 0" type="cylinder" rgba="0.913725 0.913725 0.847059 1" />
            <body name="FL_thigh" pos="0 0.08 0">
                <inertial pos="-0.003468 -0.018947 -0.032736" quat="0.999266 -0.00067676 -0.0382978 -0.000639813" mass="0.898919" diaginertia="0.00542178 0.00514246 0.000998869" />
                <joint name="FL_thigh_joint" pos="0 0 0" axis="0 1 0" limited="true" range="-1.0472 4.18879" />
                <geom type="mesh" contype="0" conaffinity="0" group="1" rgba="0.913725 0.913725 0.847059 1" mesh="thigh" />
                <geom size="0.1065 0.01225 0.017" pos="0 0 -0.1065" quat="0.707107 0 0.707107 0" type="box" rgba="0.913725 0.913725 0.847059 1" />
                <body name="FL_calf" pos="0 0 -0.213">
                    <inertial pos="0.00455603 0.0009473 -0.147239" quat="0.762045 0.00970173 0.0180098 0.647201" mass="0.218015" diaginertia="0.00399678 0.00398122 3.99428e-05" />
                    <joint name="FL_calf_joint" pos="0 0 0" axis="0 1 0" limited="true" range="-2.69653 -0.916298" />
                    <geom type="mesh" contype="0" conaffinity="0" group="1" rgba="0.913725 0.913725 0.847059 1" mesh="calf" />
                    <geom size="0.1065 0.008 0.008" pos="0 0 -0.1065" quat="0.707107 0 0.707107 0" type="box" rgba="0.913725 0.913725 0.847059 1" />
                    <geom size="0.01" pos="0 0 -0.213" contype="0" conaffinity="0" group="1" rgba="0 0 0 1" />
                    <geom size="0.02" pos="0 0 -0.213" rgba="0 0 0 1" />
                </body>
            </body>
        </body>
        <body name="RR_hip" pos="-0.1881 -0.04675 0">
            <inertial pos="0.00541 0.00074 6e-06" quat="0.493705 0.492582 0.506126 0.507401" mass="0.510299" diaginertia="0.000591107 0.000396595 0.000305077" />
            <joint name="RR_hip_joint" pos="0 0 0" axis="1 0 0" limited="true" range="-0.802851 0.802851" />
            <geom quat="0 0 0 -1" type="mesh" contype="0" conaffinity="0" group="1" rgba="0.913725 0.913725 0.847059 1" mesh="hip" />
            <geom size="0.046 0.02" pos="0 -0.045 0" quat="0.707107 0.707107 0 0" type="cylinder" rgba="0.913725 0.913725 0.847059 1" />
            <body name="RR_thigh" pos="0 -0.08 0">
                <inertial pos="-0.003468 0.018947 -0.032736" quat="0.999266 0.00067676 -0.0382978 0.000639813" mass="0.898919" diaginertia="0.00542178 0.00514246 0.000998869" />
                <joint name="RR_thigh_joint" pos="0 0 0" axis="0 1 0" limited="true" range="-1.0472 4.18879" />
                <geom type="mesh" contype="0" conaffinity="0" group="1" rgba="0.913725 0.913725 0.847059 1" mesh="thigh_mirror" />
                <geom size="0.1065 0.01225 0.017" pos="0 0 -0.1065" quat="0.707107 0 0.707107 0" type="box" rgba="0.913725 0.913725 0.847059 1" />
                <body name="RR_calf" pos="0 0 -0.213">
                    <inertial pos="0.00455603 0.0009473 -0.147239" quat="0.762045 0.00970173 0.0180098 0.647201" mass="0.218015" diaginertia="0.00399678 0.00398122 3.99428e-05" />
                    <joint name="RR_calf_joint" pos="0 0 0" axis="0 1 0" limited="true" range="-2.69653 -0.916298" />
                    <geom type="mesh" contype="0" conaffinity="0" group="1" rgba="0 0 0 1" mesh="calf" />
                    <geom size="0.1065 0.008 0.008" pos="0 0 -0.1065" quat="0.707107 0 0.707107 0" type="box" rgba="0 0 0 1" />
                    <geom size="0.01" pos="0 0 -0.213" contype="0" conaffinity="0" group="1" rgba="0 0 0 1" />
                    <geom size="0.02" pos="0 0 -0.213" rgba="0 0 0 1" />
                </body>
            </body>
        </body>
        <body name="RL_hip" pos="-0.1881 0.04675 0">
            <inertial pos="0.00541 -0.00074 6e-06" quat="0.507401 0.506126 0.492582 0.493705" mass="0.510299" diaginertia="0.000591107 0.000396595 0.000305077" />
            <joint name="RL_hip_joint" pos="0 0 0" axis="1 0 0" limited="true" range="-0.802851 0.802851" />
            <geom quat="0 0 1 0" type="mesh" contype="0" conaffinity="0" group="1" rgba="0.913725 0.913725 0.847059 1" mesh="hip" />
            <geom size="0.046 0.02" pos="0 0.045 0" quat="0.707107 0.707107 0 0" type="cylinder" rgba="0.913725 0.913725 0.847059 1" />
            <body name="RL_thigh" pos="0 0.08 0">
                <inertial pos="-0.003468 -0.018947 -0.032736" quat="0.999266 -0.00067676 -0.0382978 -0.000639813" mass="0.898919" diaginertia="0.00542178 0.00514246 0.000998869" />
                <joint name="RL_thigh_joint" pos="0 0 0" axis="0 1 0" limited="true" range="-1.0472 4.18879" />
                <geom type="mesh" contype="0" conaffinity="0" group="1" rgba="0.913725 0.913725 0.847059 1" mesh="thigh" />
                <geom size="0.1065 0.01225 0.017" pos="0 0 -0.1065" quat="0.707107 0 0.707107 0" type="box" rgba="0.913725 0.913725 0.847059 1" />
                <body name="RL_calf" pos="0 0 -0.213">
                    <inertial pos="0.00455603 0.0009473 -0.147239" quat="0.762045 0.00970173 0.0180098 0.647201" mass="0.218015" diaginertia="0.00399678 0.00398122 3.99428e-05" />
                    <joint name="RL_calf_joint" pos="0 0 0" axis="0 1 0" limited="true" range="-2.69653 -0.916298" />
                    <geom type="mesh" contype="0" conaffinity="0" group="1" rgba="0 0 0 1" mesh="calf" />
                    <geom size="0.1065 0.008 0.008" pos="0 0 -0.1065" quat="0.707107 0 0.707107 0" type="box" rgba="0 0 0 1" />
                    <geom size="0.01" pos="0 0 -0.213" contype="0" conaffinity="0" group="1" rgba="0 0 0 1" />
                    <geom size="0.02" pos="0 0 -0.213" rgba="0 0 0 1" />
                </body>
            </body>
        </body>
    </worldbody>

    <actuator>
        <motor class ="abduction" name = "FR_hip" joint ="FR_hip_joint" />
        <motor class ="hip" name = "FR_thigh" joint ="FR_thigh_joint" />
        <motor class ="knee" name = "FR_calf" joint ="FR_calf_joint" />
        <motor class ="abduction" name = "FL_hip" joint ="FL_hip_joint" />
        <motor class ="hip" name = "FL_thigh" joint ="FL_thigh_joint" />
        <motor class ="knee" name = "FL_calf" joint ="FL_calf_joint" />
        <motor class ="abduction" name = "RR_hip" joint ="RR_hip_joint" />
        <motor class ="hip" name = "RR_thigh" joint ="RR_thigh_joint" />
        <motor class ="knee" name = "RR_calf" joint ="RR_calf_joint" />
        <motor class ="abduction" name = "RL_hip" joint ="RL_hip_joint" />
        <motor class ="hip" name = "RL_thigh" joint ="RL_thigh_joint" />
        <motor class ="knee" name = "RL_calf" joint ="RL_calf_joint" />

    </actuator>

    <sensor>
        <jointpos name="FR_hip_pos" joint="FR_hip_joint" />
        <jointpos name="FR_thigh_pos" joint="FR_thigh_joint" />
        <jointpos name="FR_calf_pos" joint="FR_calf_joint" />
        <jointpos name="FL_hip_pos" joint="FL_hip_joint" />
        <jointpos name="FL_thigh_pos" joint="FL_thigh_joint" />
        <jointpos name="FL_calf_pos" joint="FL_calf_joint" />
        <jointpos name="RR_hip_pos" joint="RR_hip_joint" />
        <jointpos name="RR_thigh_pos" joint="RR_thigh_joint" />
        <jointpos name="RR_calf_pos" joint="RR_calf_joint" />
        <jointpos name="RL_hip_pos" joint="RL_hip_joint" />
        <jointpos name="RL_thigh_pos" joint="RL_thigh_joint" />
        <jointpos name="RL_calf_pos" joint="RL_calf_joint" />

        <jointvel name="FR_hip_vel" joint="FR_hip_joint" />
        <jointvel name="FR_thigh_vel" joint="FR_thigh_joint" />
        <jointvel name="FR_calf_vel" joint="FR_calf_joint" />
        <jointvel name="FL_hip_vel" joint="FL_hip_joint" />
        <jointvel name="FL_thigh_vel" joint="FL_thigh_joint" />
        <jointvel name="FL_calf_vel" joint="FL_calf_joint" />
        <jointvel name="RR_hip_vel" joint="RR_hip_joint" />
        <jointvel name="RR_thigh_vel" joint="RR_thigh_joint" />
        <jointvel name="RR_calf_vel" joint="RR_calf_joint" />
        <jointvel name="RL_hip_vel" joint="RL_hip_joint" />
        <jointvel name="RL_thigh_vel" joint="RL_thigh_joint" />
        <jointvel name="RL_calf_vel" joint="RL_calf_joint" />



        <framequat name="imu_quat" objtype="site" noise="0.001" objname="imu"/>
        <framepos name="frame_pos" objtype="site" noise="0.001" objname="imu"/>
        <gyro name="imu_gyro" site="imu" noise="0.005" cutoff="34.9"/>
        <velocimeter name="linear-velocity" site="imu" noise="0.001" cutoff="30"/>
        <accelerometer name="linear-acceleration" site="imu" noise="0.005" cutoff="157"/>
        <magnetometer name="magnetometer" site="imu"/>
    </sensor>
        
</mujoco>
